<?xml version="1.0" ?>
<!-- =================================================================================== -->
<!-- |    This document was autogenerated by xacro from kuka_kr6.urdf.xacro            | -->
<!-- |    EDITING THIS FILE BY HAND IS NOT RECOMMENDED                                 | -->
<!-- =================================================================================== -->
<robot name="kuka_kr6" xmlns:xacro="http://www.ros.org/wiki/xacro">
  <!-- Parameters -->
  <!-- Constants -->
  <!-- Dynamics -->
  <!-- Friccion -->
  <!-- Inertial cuboid element -->
  <!-- Same def that box primitive (center) -->
  <!-- Same def that box primitive -->
  <!-- Inertial sphere element -->
  <!-- Inertial cylinder element -->
  <!-- Axis along z (length) -->
  <!-- Inertial dummy element -->
  <!-- URDF Materials -->
  <material name="Grey1">
    <color rgba="0.1 0.1 0.1 1"/>
  </material>
  <material name="Grey2">
    <color rgba="0.2 0.2 0.2 1"/>
  </material>
  <material name="Grey3">
    <color rgba="0.3 0.3 0.3 1"/>
  </material>
  <material name="KUKA_Orange">
    <color rgba="0.2 0.2 0.2 1"/>
  </material>
  <!-- Gazebo macros -->
  <!-- ROS Control -->
  <gazebo>
    <plugin filename="libgazebo_ros_control.so" name="ros_control">
      <robotNamespace>/lhd</robotNamespace>
    </plugin>
  </gazebo>
  <!-- For Effort controllers -->
  <!-- For Position controllers -->
  <!-- No gravity links -->
  <!-- Normal links -->
  <!-- Wheel links -->
  <!-- Gripper links -->
  <!-- Depth camera plugin -->
  <!-- Base wheels plugin -->
  <!-- Hokuyo plugin -->
  <!-- KUKA KR6 -->
  <!-- KUKA Main -->
  <!-- Joint limits -->
  <!-- Effort -->
  <!-- Joint velocity -->
  <!-- **************************************** -->
  <!-- Base link -->
  <link name="base_link">
    <visual>
      <origin rpy="0 0 0" xyz="0 0 0"/>
      <geometry>
        <mesh filename="package://kuka_description/meshes/visual/base_link.stl"/>
      </geometry>
      <material name="Grey3"/>
    </visual>
    <collision>
      <origin rpy="0 0 0" xyz="0 0 0"/>
      <geometry>
        <mesh filename="package://kuka_description/meshes/visual/base_link.stl"/>
      </geometry>
    </collision>
  </link>
  <!-- **************************************** -->
  <!-- A1 -->
  <!-- Joint A1 -->
  <joint name="joint_a1" type="revolute">
    <origin rpy="0 0 0" xyz="0 0 0.35"/>
    <parent link="base_link"/>
    <child link="link_1"/>
    <axis xyz="0 0 -1"/>
    <limit effort="80" lower="-3.14159265359" upper="3.14159265359" velocity="2.72271363311"/>
  </joint>
  <!-- Link 1 -->
  <link name="link_1">
    <inertial>
      <origin rpy="0 0 0" xyz="0 0 0"/>
      <mass value="2.0"/>
      <inertia ixx="0.2" ixy="0.0" ixz="0.0" iyy="0.2" iyz="0.0" izz="0.2"/>
    </inertial>
    <visual>
      <origin rpy="0 0 0" xyz="0 0 0"/>
      <geometry>
        <mesh filename="package://kuka_description/meshes/visual/link_1.stl"/>
      </geometry>
      <material name="KUKA_Orange"/>
    </visual>
    <collision>
      <origin rpy="0 0 0" xyz="0 0 0"/>
      <geometry>
        <mesh filename="package://kuka_description/meshes/visual/link_1.stl"/>
      </geometry>
    </collision>
  </link>
  <!-- **************************************** -->
  <!-- A2 -->
  <!-- Joint A2 -->
  <joint name="joint_a2" type="revolute">
    <origin rpy="0 0 0" xyz="0.3 -0.068 0.315"/>
    <parent link="link_1"/>
    <child link="link_2"/>
    <axis xyz="0 1 0"/>
    <!-- Offset de -90 -->
    <limit effort="80" lower="-0.698131700798" upper="1.2217304764" velocity="2.72271363311"/>
  </joint>
  <!-- Link 2-->
  <link name="link_2">
    <inertial>
      <origin rpy="0 0 0" xyz="0 0 0"/>
      <mass value="2.0"/>
      <inertia ixx="0.2" ixy="0.0" ixz="0.0" iyy="0.2" iyz="0.0" izz="0.2"/>
    </inertial>
    <visual>
      <origin rpy="0 0 0" xyz="0 0 0"/>
      <geometry>
        <mesh filename="package://kuka_description/meshes/visual/link_2.stl"/>
      </geometry>
      <material name="KUKA_Orange"/>
    </visual>
    <collision>
      <origin rpy="0 0 0" xyz="0 0 0"/>
      <geometry>
        <mesh filename="package://kuka_description/meshes/visual/link_2.stl"/>
      </geometry>
    </collision>
  </link>
  <!-- **************************************** -->
  <!-- A3 -->
  <!-- Joint A3 -->
  <joint name="joint a3" type="revolute">
    <origin rpy="0 0 0" xyz="0 -0.011 0.65"/>
    <parent link="link_2"/>
    <child link="link_3"/>
    <axis xyz="0 0.99939 -0.034899"/>
    <!-- Offset +90 -->
    <limit effort="80" lower="-3.57792496659" upper="1.1344640138" velocity="2.72271363311"/>
  </joint>
  <!-- Link 3 -->
  <link name="link_3">
    <inertial>
      <origin rpy="0 0 0" xyz="0 0 0"/>
      <mass value="2.0"/>
      <inertia ixx="0.2" ixy="0.0" ixz="0.0" iyy="0.2" iyz="0.0" izz="0.2"/>
    </inertial>
    <visual>
      <origin rpy="0 0 0" xyz="0 0 0"/>
      <geometry>
        <mesh filename="package://kuka_description/meshes/visual/link_3.stl"/>
      </geometry>
      <material name="KUKA_Orange"/>
    </visual>
    <collision>
      <origin rpy="0 0 0" xyz="0 0 0"/>
      <geometry>
        <mesh filename="package://kuka_description/meshes/visual/link_3.stl"/>
      </geometry>
    </collision>
  </link>
  <!-- **************************************** -->
  <!-- A4 -->
  <!-- Joint A4 -->
  <joint name="joint_a4" type="revolute">
    <origin rpy="0 0 0" xyz="0.358 0.08636 0.15208"/>
    <parent link="link_3"/>
    <child link="link_4"/>
    <axis xyz="-1 0 0"/>
    <limit effort="80" lower="-6.02138591938" upper="6.02138591938" velocity="5.98647933434"/>
  </joint>
  <!-- Link 4 -->
  <link name="link_4">
    <inertial>
      <origin rpy="0 0 0" xyz="0 0 0"/>
      <mass value="2.0"/>
      <inertia ixx="0.2" ixy="0.0" ixz="0.0" iyy="0.2" iyz="0.0" izz="0.2"/>
    </inertial>
    <visual>
      <origin rpy="0 0 0" xyz="0 0 0"/>
      <geometry>
        <mesh filename="package://kuka_description/meshes/visual/link_4.stl"/>
      </geometry>
      <material name="KUKA_Orange"/>
    </visual>
    <collision>
      <origin rpy="0 0 0" xyz="0 0 0"/>
      <geometry>
        <mesh filename="package://kuka_description/meshes/visual/link_4.stl"/>
      </geometry>
    </collision>
  </link>
  <!-- **************************************** -->
  <!-- A5 -->
  <!-- Joint A5 -->
  <joint name="joint_a5" type="revolute">
    <origin rpy="0 0 0" xyz="0.242 0.020238 -0.00070671"/>
    <parent link="link_4"/>
    <child link="link_5"/>
    <axis xyz="0 1 0"/>
    <limit effort="80" lower="-1.91986217719" upper="1.3962634016" velocity="6.31809189222"/>
  </joint>
  <!-- Link 5 -->
  <link name="link_5">
    <inertial>
      <origin rpy="0 0 0" xyz="0 0 0"/>
      <mass value="2.0"/>
      <inertia ixx="0.2" ixy="0.0" ixz="0.0" iyy="0.2" iyz="0.0" izz="0.2"/>
    </inertial>
    <visual>
      <origin rpy="0 0 0" xyz="0 0 0"/>
      <geometry>
        <mesh filename="package://kuka_description/meshes/visual/link_5.stl"/>
      </geometry>
      <material name="KUKA_Orange"/>
    </visual>
    <collision>
      <origin rpy="0 0 0" xyz="0 0 0"/>
      <geometry>
        <mesh filename="package://kuka_description/meshes/visual/link_5.stl"/>
      </geometry>
    </collision>
  </link>
  <!-- **************************************** -->
  <!-- A6 -->
  <!-- Joint A6 -->
  <joint name="joint_a6" type="revolute">
    <origin rpy="0 0 0" xyz="0.1125 -0.02025 0"/>
    <parent link="link_5"/>
    <child link="link_6"/>
    <axis xyz="-1 0 0"/>
    <limit effort="80" lower="-6.02138591938" upper="6.02138591938" velocity="6.31809189222"/>
  </joint>
  <!-- Link 6 -->
  <link name="link_6">
    <inertial>
      <origin rpy="0 0 0" xyz="0 0 0"/>
      <mass value="2.0"/>
      <inertia ixx="0.2" ixy="0.0" ixz="0.0" iyy="0.2" iyz="0.0" izz="0.2"/>
    </inertial>
    <visual>
      <origin rpy="0 0 0" xyz="0 0 0"/>
      <geometry>
        <mesh filename="package://kuka_description/meshes/visual/link_6.stl"/>
      </geometry>
      <material name="Grey1"/>
    </visual>
    <collision>
      <origin rpy="0 0 0" xyz="0 0 0"/>
      <geometry>
        <mesh filename="package://kuka_description/meshes/visual/link_6.stl"/>
      </geometry>
    </collision>
  </link>
</robot>

